Workbook
Name Assessment: #REF!
Name Domain: #REF!
Name Health_Promotion: #REF!
Name Planning_and_Management: #REF!
Name Professional_Responsibilities: #REF!
Name Stage: 'Internal - tracking items'!$A$2:$A$10
Name System: #REF!
Name Workflow: 'Internal - tracking items'!$G$2:$G$6

Sheet Plan by domain (not used)
A2: Domain | B2: Subdomain | D2: Recall Items (Planned) | E2: Application Items (Planned) | F2: Analysis Items (Planned) | G2: Total (Planned) | H2: Submitted (from Items tab) | I2: Assigned total (See Writer entries to the right) | J2: Writer1 | K2: Writer2 | L2: Writer3 | M2: Writer4 | N2: Uncommitted | O2: Deviation from plan
D3: =SUM(D4:D39) -> 0 | E3: =SUM(E4:E39) -> 0 | F3: =SUM(F4:F39) -> 0 | G3: =SUM(D3:F3) -> 0 | H3: =SUM(H4:H39) -> #REF! | I3: =SUM(I4:I39) -> 0 | J3: =SUM(J4:J39) -> 0 | K3: =SUM(K4:K39) -> 0 | L3: =SUM(L4:L39) -> 0 | M3: =SUM(M4:M39) -> 0 | N3: =SUM(N4:N39) -> 0
A4: Domain1 | B4: Subdomain1_1 | G4: =SUM(D4:F4) -> 0 | H4: =#REF! -> #REF! | I4: =SUM(J4:M4) -> 0 | N4: =G4-I4 -> 0 | O4: =H4-G4 -> #REF!
A5: Domain1 | B5: Subdomain2_1 | G5: =SUM(D5:F5) -> 0 | H5: =#REF! -> #REF! | I5: =SUM(J5:M5) -> 0 | O5: =H5-G5 -> #REF!
A6: Domain1 | B6: Subdomain3_1 | G6: =SUM(D6:F6) -> 0 | H6: =#REF! -> #REF! | I6: =SUM(J6:M6) -> 0 | O6: =H6-G6 -> #REF!
A7: Domain1 | B7: Subdomain4_1 | G7: =SUM(D7:F7) -> 0 | H7: =#REF! -> #REF! | I7: =SUM(J7:M7) -> 0 | O7: =H7-G7 -> #REF!
A8: Domain1 | B8: Subdomain5_1 | G8: =SUM(D8:F8) -> 0 | H8: =#REF! -> #REF! | I8: =SUM(J8:M8) -> 0 | O8: =H8-G8 -> #REF!
A9: Domain1 | B9: Subdomain6_1 | G9: =SUM(D9:F9) -> 0 | H9: =#REF! -> #REF! | I9: =SUM(J9:M9) -> 0 | O9: =H9-G9 -> #REF!
A10: Domain2 | B10: Subdomain1_2 | G10: =SUM(D10:F10) -> 0 | H10: =#REF! -> #REF! | I10: =SUM(J10:M10) -> 0 | O10: =H10-G10 -> #REF!
A11: Domain2 | B11: Subdomain2_2 | G11: =SUM(D11:F11) -> 0 | H11: =#REF! -> #REF! | I11: =SUM(J11:M11) -> 0 | O11: =H11-G11 -> #REF!
A12: Domain2 | B12: Subdomain3_2 | G12: =SUM(D12:F12) -> 0 | H12: =#REF! -> #REF! | I12: =SUM(J12:M12) -> 0 | O12: =H12-G12 -> #REF!
A13: Domain2 | B13: Subdomain4_2 | G13: =SUM(D13:F13) -> 0 | H13: =#REF! -> #REF! | I13: =SUM(J13:M13) -> 0 | O13: =H13-G13 -> #REF!
A14: Domain2 | B14: Subdomain5_2 | G14: =SUM(D14:F14) -> 0 | H14: =#REF! -> #REF! | I14: =SUM(J14:M14) -> 0 | O14: =H14-G14 -> #REF!
A15: Domain2 | B15: Subdomain6_2 | G15: =SUM(D15:F15) -> 0 | H15: =#REF! -> #REF! | I15: =SUM(J15:M15) -> 0 | O15: =H15-G15 -> #REF!
A16: Domain3 | B16: Subdomain1_3 | G16: =SUM(D16:F16) -> 0 | H16: =#REF! -> #REF! | I16: =SUM(J16:M16) -> 0 | O16: =H16-G16 -> #REF!
... A39: Domain6 | B39: Subdomain6_6 | G39: =SUM(D39:F39) -> 0 | H39: =#REF! -> #REF! | I39: =SUM(J39:M39) -> 0 | O39: =H39-G39 -> #REF!

Sheet SPC-CPN_Q&A
A1: Unique ID Number | B1: Chapter Number | C1: Item Number in Chapter | D1: Item Type (Practice Question or Test Question?) | E1: Stem | F1: A | G1: B | H1: C | I1: D | J1: Correct Answer | K1: Correct Option | L1: Rationale | M1: CPN Domain | N1: SPC Topic | O1: Cognitive Level
A2: 1 | B2: 1 | C2: 1 | D2: Practice | E2: What is the STRONGEST outcome predictor for submersion injuries? | F2: Submersion duration | G2: Temperature of the water | H2: Type of water | I2: Length of resuscitation | J2: Submersion duration | K2: A | L2: The strongest outcome predictor for submersion injuries is submersion duration. Durations of fewer than 5 minutes are associated with more favorable outcomes. The worst outcomes occur when submersion duration is longer than 25 minutes. Submersion in colder, fresh water is correlated with better outcomes, but these factors are not the strongest predictors of outcome. Length of resuscitation is not a predictor of outcome in submersion injuries. | M2: Health_Promotion | O2: Recall
A3: 2 | B3: 4 | C3: 1 | D3: Practice | E3: A child from a divorced family discloses that they have not gone to school in 4 weeks because their father does not take them. The nurse's BEST action is to: | F3: Advise the child to suggest home schooling to the father | G3: Notify a case manager so transportation to school can be arranged | H3: Notify child protective services | I3: Inform the child's mother about the situation | J3: Notify child protective services | K3: C | L3: The child needs to be provided with basic education, and failing to do so is a form of neglect. The nurse should alert child protective services to investigate the child’s home life. Child protective services may assign a case manager, who will ensure that the father has the means to take the child to school or will provide guidance and direction if home schooling is an option for the father. In addition, child protective services would be responsible for notifying the child's mother about the situation. | M3: Professional_Responsibilities | N3: Neglect | O3: Application
A4: 4 | B4: 2 | C4: 1 | D4: Practice | E4: Which of the following should be heard when auscultating the chest of a patient with a Norwood repair? | F4: Shunt murmur | G4: No murmur | H4: Shunt clicks | I4: No clicks | J4: Shunt murmur | K4: A | L4: During a Norwood repair, a round tube or shunt routes blood either from the aorta or directly from the right ventricle to the pulmonary artery. Blood flowing through this repair will result in a murmur in the left upper chest, not a click, which is usually associated with valves. A murmur indicates that the shunt is patent. No murmur indicates that the Norwood repair is not functioning. | M4: Assessment | O4: Recall
A5: 5 | B5: 2 | C5: 2 | D5: Practice | E5: Which of the following is the MOST appropriate technique for assessing the tympanic membrane in a 3-year-old patient? | F5: Pull the pinnae of the ear upward and forward | G5: Pull the pinnae of the ear upward and backward | H5: Pull the pinnae of the ear downward and forward | I5: Pull the pinnae of the ear downward and backward | J5: Pull the pinnae of the ear upward and backward | K5: B | L5: Ear canals of patients who are 3 years or older curve downward and forward, and the drum slopes inward and forward. To visualize the tympanic membrane via an otoscope, the pinnae of the ear must be pulled upward and backward. Ear canals of infants curve upward, and the tympanic membrane is horizontal along the upper wall of the canal. Therefore, the pinnae of the ear must be pulled downward and backward to visualize the tympanic membrane. Pulling the pinnae upward and forward or downward and forward will not help visualize the membrane. | M5: Assessment | O5: Application
A6: 6 | B6: 2 | C6: 3 | D6: Practice | E6: The nurse is stroking the corner of a 2-month-old patient’s mouth. Which reflex is the nurse trying to elicit? | F6: Moro | G6: Sucking | H6: Rooting | I6: Tonic neck | J6: Rooting | K6: C | L6: Stroking the corner of the mouth will elicit the rooting reflex. The infant will move their head toward stimulation if the reflex is present. The sucking reflex is elicited by touching the infant’s lips with a finger. The Moro reflex is eliciting by making a loud noise or bracing the patient’s head and back while simulating falling. The infant will extend and flex the arms and fingers. To elicit the tonic neck reflex, the infant's head is turned to one side, and the upper and lower extremities on that side will extend while the opposite extremities flex. | M6: Assessment | O6: Recall
A7: 7 | B7: 2 | C7: 4 | D7: Practice | E7: What structure is being assessed when the nurse pushes the tip of the patient's nose upward and asks them to tilt their head back? | F7: Pinna | G7: Choroid | H7: Frenulum | I7: Anterior vestibule | J7: Anterior vestibule | K7: D | L7: The nurse can inspect the anterior vestibule of the nose by pushing the tip upward, tilting the head backward, and shining a light into the cavity. The tongue is attached to the floor of the mouth by a fold called the frenulum. The pinna, or auricle, is the exterior part of the ear. The choroid is a tissue layer that lies between the retina and the sclera. | M7: Assessment | O7: Recall
A8: 8 | B8: 2 | C8: 5 | D8: Practice | E8: A parent presents to the clinic with their infant son, who has trisomy 21 and poor oral intake. The nurse asks the parent how they feed the child. The parent responds, “I give him the bottle, but he hardly holds it, and the milk just goes everywhere.” The nurse's BEST next action is to: | F8: Perform a feeding task analysis | G8: Conduct a swallow study | H8: Place a nasogastric tube | I8: Ask the provider to evaluate the child for placement of a gastric tube | J8: Perform a feeding task analysis | K8: A | L8: The nurse should perform a feeding task analysis, which will help to identify which element of feeding is causing the most issues. Children with trisomy 21 (Down syndrome) may struggle with eating due to laxity in muscles, floppy head, and tongue protrusion that pushes food out. It is not appropriate to immediately place a nasogastric tube prior to assessing the child and his ability to feed orally. Once the study is complete, the nurse can ask the provider to evaluate the child for placement of a gastric tube. A swallow study can also be conducted after a feeding task analysis to ensure the child is not aspirating food. | M8: Assessment | O8: Analysis
A9: 9 | B9: 2 | C9: 6 | D9: Practice | E9: The nurse is assessing a male child who has a long face with a prominent jaw and large ears. The child is rocking back and forth during the assessment. The nurse recognizes these characteristics as features of: | F9: Down syndrome | G9: Fragile X syndrome | H9: Turner syndrome | I9: Trisomy 18 | J9: Fragile X syndrome | K9: B | L9: Classic characteristics of fragile X syndrome include a long face; prominent jaw; large, protruding ears; and autism-like behaviors such as rocking or fidgeting. Down syndrome presents with a flattened nasal bridge, almond-shaped eyes, short neck, and small ears. Only female patients are affected by Turner syndrome. They present with a web-like neck, a broad chest, and a high/narrow roof of the mouth. Children with trisomy 18 have small, abnormally shaped heads; small jaws; and clenched fists with overlapping fingers. | M9: Assessment | O9: Application
A10: 10 | B10: 5 | C10: 1 | D10: Test | E10: The nurse is assessing a 6-month-old patient who was brought to the ED with a low-grade fever, poor feeding, and restlessness. The infant has increased respiratory secretions, and the parents are concerned that the infant is having trouble breathing. Which monitoring intervention will the nurse PRIORITIZE until the patient is transferred to the pediatric ICU? | F10: Pediatric Glasgow Coma Scale | G10: Intake and output | H10: Cardiac rate and rhythm | I10: Frequent vital signs | J10: Pediatric Glasgow Coma Scale | K10: A | L10: The nurse will prioritize monitoring the infant’s level of consciousness using the pediatric Glasgow Coma Scale. If the patient becomes increasingly lethargic and less responsive, the nurse will take further action to assess the patient’s respiratory status and address any need for additional intervention. The nurse will also continue to assess the patient’s hemodynamic status by evaluating intake and output, monitoring cardiac rate and rhythm, and collecting frequent vital signs. | M10: Assessment | O10: Application
A11: 11 | B11: 2 | C11: 7 | D11: Practice | E11: While assessing a neonate, the nurse notes small, yellow-white, epithelial cysts along the roof of the infant’s mouth. The nurse recognizes these cysts as: | F11: Abscesses | G11: Epstein pearls | H11: Herpes simplex | I11: Koplik spots | J11: Epstein pearls | K11: B | L11: Epstein pearls are whitish-yellow cysts that form on the gums and roof of the mouth in newborns. The cysts contain keratin, a protein that occurs naturally in human skin, hair, and nails. Epstein pearls are a normal finding and resolve within a few weeks of birth. Abscesses form from infected wounds and contain a mixture of white blood cells and pus. Herpes simplex type 1 is a viral infection that presents with external sores and blisters on the mouth. Koplik spots, tiny white spots in the mouth, are a prodromal manifestation of the measles infection. | M11: Assessment | O11: Recall
A12: 13 | B12: 2 | C12: 8 | D12: Practice | E12: Which of the following are common clinical manifestations of HIV infection in children? | F12: Recurrent diarrhea, failure to thrive, developmental delay, and petechiae | G12: Oral candidiasis, recurrent diarrhea, petechiae, and epistaxis | H12: Failure to thrive, developmental delay, petechiae, and epistaxis | I12: Oral candidiasis, chronic diarrhea, failure to thrive, and developmental delay | J12: Oral candidiasis, chronic diarrhea, failure to thrive, and developmental delay | K12: D | L12: Common clinical manifestations of HIV are lymphadenopathy, hepatosplenomegaly, oral candidiasis, chronic or recurrent diarrhea, failure to thrive, developmental delay, and parotitis. Petechiae and epistaxis are common clinical manifestations of immune thrombocytopenia. | M12: Assessment | O12: Recall
A13: 14 | B13: 2 | C13: 9 | D13: Practice | E13: An infant admitted for shaken baby syndrome has poor capillary refill, tachypnea, and falling blood pressure. The nurse should recognize the patient is MOST likely experiencing which type of shock? | F13: Hypovolemic | G13: Distributive | H13: Cardiogenic | I13: Irreversible | J13: Hypovolemic | K13: A | L13: Shaken baby syndrome can cause bleeding into the brain, resulting in hypovolemic shock. Distributive shock occurs when there is an abnormal distribution of blood flow in the smallest blood vessels, resulting in inadequate supply of blood to the body’s tissues and organs. Cardiogenic shock is a medical emergency caused by inadequate blood flow due to the dysfunction of the ventricles of the heart. Injuries to the chest, abdomen, or pelvis, where hemorrhage can be difficult to detect and control, usually cause irreversible shock, which is often a fatal condition. | M13: Assessment | O13: Application
A14: 15 | B14: 2 | C14: 10 | D14: Practice | E14: Which of the following conditions are associated with a risk for a latex allergy? | F14: Imperforate anus, spina bifida, and prematurity | G14: Imperforate anus, prematurity, and Meckel diverticulum | H14: Imperforate anus, spina bifida, and Meckel diverticulum | I14: Spinal bifida, prematurity, and Meckel diverticulum | J14: Imperforate anus, spina bifida, and prematurity | K14: A | L14: Medical conditions associated with risk for latex allergy are spina bifida, urogenital anomalies, imperforate anus, tracheoesophageal fistula, VATER association (a group of birth defects that present together), prematurity, ventriculoperitoneal shunt, congenital impairment, cerebral palsy, spinal cord injuries, multiple surgeries, and atopy. Meckel diverticulum is a remnant of the fetal omphalomesenteric duct, which connects the yolk sac with the primitive midgut during fetal life. It is not associated with latex allergy. | M14: Assessment | O14: Recall
A15: 16 | B15: 2 | C15: 11 | D15: Practice | E15: Which of the following are common clinical manifestations of a cow’s milk allergy? | F15: Sneezing, pallor, fussiness, and bradycardia | G15: Atopic dermatitis, pallor, fussiness, and dysrhythmia | H15: Sneezing, atopic dermatitis, pallor, and fussiness | I15: Atopic dermatitis, fussiness, bradycardia, and sneezing | J15: Sneezing, atopic dermatitis, pallor, and fussiness | K15: C | L15: Cow’s milk allergy commonly manifests as sneezing, atopic dermatitis, pallor, and fussiness. While bradycardia and dysrhythmia are common indications of a severe allergy attack, they are not commonly found with a cow’s milk allergy. | M15: Assessment | O15: Recall
... A107: 115 | B107: 3 | C107: 23 | D107: Practice | E107: A child is undergoing suture repair of a laceration to the lower leg. The nurse instructs the patient that the sutures will be removed in how many days? | F107: 3 to 5 | G107: 5 to 7 | H107: 7 to 10 | I107: 10 to 14 | J107: 10 to 14 | K107: D | L107: Sutures to the lower legs and feet should be removed in 10 to 14 days. Most sutures in the face are removed in 3 to 5 days, but some face sutures, as well as scalp sutures, are removed in 5 to 7 days. Sutures on the torso are removed in 7 to 10 days. | M107: Planning_and_Management | O107: Recall
A108: 116 | B108: 4 | C108: 2 | D108: Practice | E108: The nurse is teaching the parents of a child with terminal cancer the differences between hospice care and palliative care. Which of the following statements by the nurse is MOST accurate? | F108: "Both hospice care and palliative care are provided for terminally ill patients only." | G108: "Palliative care can be provided to patients with a life expectancy of 12 months or less." | H108: "Unlike hospice care, palliative care is provided in the home setting only." | I108: "Life-prolonging medications can be used in palliative care but not in hospice care." | J108: "Life-prolonging medications can be used in palliative care but not in hospice care." | K108: D | L108: A key difference between hospice care and palliative care is the type of care that is provided. In palliative care, life-prolonging medications and equipment can be used, whereas in hospice care, curative and life-prolonging treatments cannot be provided. Another key difference is that palliative care is available to patients in all disease stages; life expectancy is not a factor. Hospice admission criteria require that the patient have a life expectancy of 6 months or less. Both hospice care and palliative care can take place in a variety of settings, although the majority of hospice care programs are home based. | M108: Professional_Responsibilities | N108: End of life | O108: Recall
A109: 117 | B109: 3 | C109: 24 | D109: Practice | E109: The nurse is teaching the parent of a child who is receiving palliative care about measuring oral medication using a dropper. The parent speaks English as a second language and has low proficiency. What is the BEST way to ensure that the instructions are understood? | F109: Provide hands-on learning with a dropper using water to practice | G109: Ask the parent to teach-back the skill being taught | H109: Provide written instructions after verbal instructions | I109: Arrange for a nurse’s aide to administer the medication | J109: Ask the parent to teach-back the skill being taught | K109: B | L109: To provide proper care for a child who is receiving palliative care, the family must be well-informed regarding the illness, disease progression, medication use, and use of equipment. The nurse must identify barriers to family education, such as low English proficiency, low literacy, low confidence, family dynamics, and cultural beliefs regarding care during illness. The best way to ensure that the instructions are understood and that the parent can complete the skill is to use the teach-back method. Hands-on practice can be provided, but the teach-back method more effectively ensures that the parent understands the skill well enough to explain it step by step. Verbal instructions can be supplemented with written instructions, but this does not ensure that the instructions have been understood. There is no evidence that the parent is unable to complete the skill; therefore, the nurse does not need to arrange for an aide to administer the medication. | M109: Planning_and_Management | O109: Analysis
A110: 118 | B110: 5 | C110: 29 | D110: Test | E110: During a death vigil, the MOST appropriate nursing intervention is to: | F110: Teach the family about the dying process | G110: Determine cultural needs at the time of death | H110: Arrange a team meeting to prepare for the loss | I110: Keep family members separated from the patient | J110: Teach the family about the dying process | K110: A | L110: When a child is approaching death, family members will draw near to spend the last days or hours with the child. This time is often referred to as the death vigil. The nurse can provide the most support for the family by teaching them about the process of dying. Any cultural considerations would have been determined earlier in the hospice process. It is not necessary to arrange for a team meeting to prepare for the loss. | M110: Planning_and_Management | O110: Application
A111: 119 | B111: 5 | C111: 30 | D111: Test | E111: The nurse is managing a patient who has undergone a cleft palate repair. Which of the following nursing interventions is MOST critical? | F111: Maintain an intact suture line | G111: Use a syringe or a cup when feeding | H111: Position the patient on their abdomen or side | I111: Keep hard and pointed objects away from the patient’s mouth | J111: Position the patient on their abdomen or side | K111: C | L111: Positioning the patient on their abdomen or side allows for a patent airway. Maintaining a patent airway is the most critical nursing intervention. The nurse should also assess for signs of respiratory distress. Using a syringe or cup during feedings helps prevent injury to the suture line, and rinsing and cleaning the suture line helps to maintain its integrity. However, these actions are not the most critical intervention. While keeping hard and pointed objects away from the patient is an important component of the plan, it is also not the most critical intervention. | M111: Planning_and_Management | O111: Analysis
A112: 120 | B112: 3 | C112: 25 | D112: Practice | E112: A parent brings their 13-year-old child to the clinic with a complaint of a nonpruritic lesion on the child's back that is more pronounced when exposed to sunlight. The nurse notes small areas of pigmented, dry skin. The nurse suspects that the patient has: | F112: Atopic dermatitis | G112: Folliculitis | H112: Contact dermatitis | I112: Tinea versicolor | J112: Tinea versicolor | K112: D | L112: The nurse recognizes that the patient likely has tinea versicolor, which is a fungal infection that interferes with normal pigmentation of the skin. The patient may have small, nonpruritic lesions that are lighter or darker than the surrounding skin. The lesions can be more pronounced when exposed to sunlight. Atopic dermatitis (eczema) is an inflammatory condition characterized by pruritic plaques on the skin. Folliculitis is an inflammation of the hair follicles that is typically caused by a Staphylococcus aureus infection. It is characterized by small red bumps or white-headed pimples around the follicles. Contact dermatitis is an inflammatory condition that develops as a response to an allergen or irritant. It is characterized by erythematous and pruritic skin lesions that appear after contact with a foreign substance. | M112: Planning_and_Management | O112: Application
A113: 121 | B113: 3 | C113: 26 | D113: Practice | E113: The nurse is caring for a 3-year-old patient who has been hospitalized for a week. The child is toilet-trained but is now urinating in the hospital bed. The nurse recognizes that the child is demonstrating: | F113: Self-assertion | G113: Regression | H113: Detachment | I113: Anger | J113: Regression | K113: B | L113: In times of stress, children may experience a temporary loss of developmental milestones, which is termed regression. A child may voice their wants due to their sense of autonomy (self-assertion), but this is not a manifestation of loss of a developmental milestone. Detachment is a break in the bond between parent and child that typically occurs after a prolonged separation. The child may be angry at their parents or at the situation, but that anger is unlikely to result in a developmental regression such as urinating in the bed after having been toilet-trained. | M113: Planning_and_Management | O113: Application
A114: 122 | B114: 3 | C114: 27 | D114: Practice | E114: The nurse is preparing to explain to a 4-year-old patient how a cast will be applied to their arm. Which of the following methods would MOST effectively meet the developmental needs of the child? | F114: Using a doll to demonstrate the casting procedure | G114: Explaining the procedure as it is performed | H114: Showing the child a diagram of the procedure | I114: Playing a video that describes the procedure | J114: Using a doll to demonstrate the casting procedure | K114: A | L114: The most effective teaching method for a preschool-aged child is to use play therapy to demonstrate the casting procedure on a doll. This will allow the child to see that the procedure is not painful and will minimize any fear of body mutilation or loss of body integrity, which is common during this period of development. This would not be effectively conveyed in a video or in explanations as the procedure is performed. The use of a diagram would be more appropriate for a school-aged child. | M114: Planning_and_Management | O114: Analysis
A115: 124 | B115: 5 | C115: 31 | D115: Test | E115: A child’s nursing diagnosis is “Constipation: Risk for, related to appendectomy and anesthetics.” Which of the following interventions is MOST appropriate on the first postoperative day? | F115: Limit activity until peristalsis has returned | G115: Offer liquids when bowel sounds are present | H115: Auscultate bowel sounds every shift | I115: Notify the provider if the child does not have a bowel movement | J115: Offer liquids when bowel sounds are present | K115: B | L115: Present bowel sounds is a sign that peristalsis has resumed and there is no paralytic ileus. The nurse can then offer the child liquids. Activity should not be limited until peristalsis has returned; instead, it should be increased as tolerated to promote gastric motility. Bowel sounds should be auscultated at least every 4 hours, not on shift change. The child is expected to have a bowel movement 3 to 4 days postoperatively, so the provider should not be contacted if there is no bowel movement on day one. | M115: Planning_and_Management | O115: Analysis
A116: 125 | B116: 3 | C116: 28 | D116: Practice | E116: Which of the following is a sign that a ventriculoperitoneal shunt is malfunctioning? | F116: Nausea and vomiting | G116: Decrease in blood pressure | H116: Lethargy and low-grade fever | I116: Febrile seizures | J116: Nausea and vomiting | K116: A | L116: A ventriculoperitoneal shunt drains excess cerebrospinal fluid when there is an obstruction in the normal outflow or decreased absorption of the fluid. It is used to treat hydrocephalus. Common signs of a malfunction include nausea and vomiting, redness over the shunt, headache, and lethargy. Fever, seizures, and low blood pressure are not signs of a malfunction. | M116: Planning_and_Management | O116: Recall
A117: 126 | B117: 5 | C117: 32 | D117: Test | E117: The nurse is educating parents on how to prevent diaper dermatitis. Which of the following will be included in the discharge instructions? | F117: Decrease the frequency of diaper changes | G117: Use zinc oxide barrier cream when changing diapers | H117: Use cloth diapers exclusively | I117: Use baby wipes with alcohol | J117: Use zinc oxide barrier cream when changing diapers | K117: B | L117: Diaper dermatitis is inflammation of the skin caused by skin irritation with urine and feces. Zinc oxide barrier cream provides the best protection against moisture in the area and will help to prevent dermatitis. Moisture increases the rash, so diapers should be changed promptly. Baby wipes with alcohol should not be used because the alcohol may further irritate the skin. There is no evidence that cloth diapers decrease moisture, so disposable diapers can be used. | M117: Planning_and_Management | O117: Application
A118: 127 | B118: 3 | C118: 29 | D118: Practice | E118: An infant is exhibiting increased effort of breathing, has a respiratory rate of 42 breaths/min, and is mildly cyanotic. Which of the following is the PRIORITY nursing intervention? | F118: Administer 100% oxygen and monitor oxygen saturation | G118: Maintain airway and reassess | H118: Administer 100% oxygen and provide comfort measures | I118: Maintain airway and administer oxygen via mask | J118: Administer 100% oxygen and monitor oxygen saturation | K118: A | L118: The child is in moderate respiratory distress with poor oxygen saturation, as evidenced by the mild cyanosis. The priority nursing intervention is to administer 100% oxygen and monitor oxygen saturation. There are no signs of an airway issue at this time, so the oxygen saturation takes precedence. | M118: Planning_and_Management | O118: Analysis
A119: 128 | B119: 3 | C119: 30 | D119: Practice | E119: The nurse is caring for a child with cystic fibrosis who receives pancreatic enzymes. Which statement by the parent demonstrates understanding of proper administration of the supplemental enzymes? | F119: “I will give the enzymes between meals for the best absorption.” | G119: “I will stop the enzymes if my child's stools become greasy.” | H119: “I will stop the enzymes if my child is given any antibiotics.” | I119: “I will give the enzymes before every meal and large snack.” | J119: “I will give the enzymes before every meal and large snack.” | K119: D | L119: In children with cystic fibrosis, the ducts in the pancreas become clogged with thick mucus, which blocks enzymes from reaching food in the small intestine. This can result in low weight gain, malnutrition, and, potentially, failure to thrive. Pancreatic enzyme replacement breaks down complex carbohydrates, fats, and proteins so that the body can absorb the calories, vitamins, and minerals required to gain and maintain weight. To maximize absorption, the enzymes should given before every meal and large snack. Greasy stools are a sign that the body is not effectively breaking down food, so the supplementation should continue to be administered. The enzymes are safe to administer with concurrent antibiotic treatment. | M119: Planning_and_Management | O119: Application
A120: 129 | B120: 3 | C120: 31 | D120: Practice | E120: The nurse is caring for a child immediately after a cardiac catheterization procedure. Which of the following is the PRIORITY nursing intervention? | F120: Assess the area proximal to the incision | G120: Apply a pressure dressing over the catheter site for several hours | H120: Elevate the head of the bed until patient comfort has been achieved | I120: Place the child on bed rest for approximately 2 hours following the procedure | J120: Apply a pressure dressing over the catheter site for several hours | K120: B | L120: A pressure dressing should be applied over the catheter site for several hours to prevent bleeding. In addition, the nurse should assess the area distal, not proximal, to the incision site. The child should be placed on bed rest for at least 6 hours to prevent disruption of the clot, which could lead to a hemorrhage. The child must lie flat to prevent hip flexion, which can predispose the child to bleeding. | M120: Planning_and_Management | O120: Application
... A256: 278 | B256: 3 | C256: 78 | D256: Practice | E256: The nurse is preparing a 3-year-old patient for morning labs. The patient was admitted for suspected child abuse due to multiple broken bones. The parents claim that the child has “brittle bones” and state that they do not abuse their child. The nurse anticipates that which of the following labs will MOST likely be ordered? | F256: Serum calcium, phosphorus, alkaline phosphatase | G256: Serum calcium, potassium, lumbar puncture | H256: Serum calcium, phosphorus, potassium | I256: Disseminated intravascular coagulation panel | J256: Serum calcium, phosphorus, alkaline phosphatase | K256: A | L256: Some bone diseases can lead to “brittle bones” and frequent fractures in different healing stages. The healthcare team should investigate all possible medical causes before concluding that the patient is being abused. Lab work would most likely include serum calcium, phosphorus, and alkaline phosphatase. A disseminated intravascular coagulation panel measures bleeding and clotting times. Lumbar puncture would be performed to test for infection. Potassium levels do not correlate with bone diseases. | M256: Planning_and_Management | O256: Analysis
A257: 279 | B257: 2 | C257: 77 | D257: Practice | E257: A 5-year-old patient is brought into the office by their father for a routine wellness check during the summer. The child has a burn mark on their right palm that is shaped like a square. The nurse's BEST action is to: | F257: Alert local authorities to suspected child abuse | G257: Treat the child for bacterial skin infection | H257: Refer the patient to the ED | I257: Educate the father on the burn wound and discharge with a scheduled follow-up | J257: Educate the father on the burn wound and discharge with a scheduled follow-up | K257: D | L257: Children can present with burn wounds on the palms for multiple reasons. Given the location and shape of the burn and the fact that it is summer, the nurse suspects that the child was burned with a seatbelt buckle. Seatbelt buckles can become extremely hot in direct sunlight and can easily burn the skin of a child. The nurse should care for the wound, educate the father on the potential source of the burn and how to avoid similar burns in the future, and schedule a follow-up. | M257: Assessment | N257: Abuse | O257: Analysis
A258: 280 | B258: 1 | C258: 26 | D258: Practice | E258: The nurse is caring for a child whose weight falls below the 10th percentile and whose length is below the 5th percentile. The plan of care would MOST likely include: | F258: Nutritional rehabilitation such as offering solid food before liquids | G258: Placement of a central line for parenteral nutrition | H258: Insertion of a percutaneous endoscopic gastrostomy tube | I258: Intravenous fluid hydration and protein shakes | J258: Nutritional rehabilitation such as offering solid food before liquids | K258: A | L258: A child with failure to thrive should first be managed with oral nutritional rehabilitation. This includes offering the child high-calorie solid foods prior to offering liquid preparations. Initial management would not include central line placement for parenteral (or intravenous) nutrition; this would be initiated if oral rehabilitation were not successful. A percutaneous endoscopic gastrostomy tube would not be placed initially. If the child is able to chew and swallow food, the oral route should not be bypassed. The use of intravenous fluid hydration and protein shakes would not provide the child with enough calories to gain weight. | M258: Health_Promotion | O258: Analysis
A259: 281 | B259: 3 | C259: 79 | D259: Practice | E259: Which medication is MOST likely to be prescribed to a 12-year-old patient diagnosed with tinea corporis? | F259: Erythromycin | G259: Mupirocin | H259: Metronidazole | I259: Itraconazole | J259: Itraconazole | K259: D | L259: Tinea corporis, also known as ringworm, is a superficial fungal infection (dermatophytosis) generally located on the arms and legs. Itraconazole is an oral antifungal used to treat this infection. Erythromycin, mupirocin, and metronidazole are antibiotics used to treat bacterial infections and are generally ineffective in the treatment of fungal infections. | M259: Planning_and_Management | O259: Application
A260: 282 | B260: 5 | C260: 75 | D260: Test | E260: The nurse is performing an assessment on a 3-month-old infant. The infant's 16-year-old mother notes that she recently dropped out of school and is staying at a male friend's apartment because her parents kicked her out of the house. Which of the following is the MOST accurate statement regarding this situation? | F260: The infant is at increased risk of cognitive delay. | G260: The mother is at increased risk of becoming an abuser. | H260: The mother is at increased risk of becoming a victim of sexual violence. | I260: The infant is at increased risk of malnutrition. | J260: The mother is at increased risk of becoming an abuser. | K260: B | L260: The mother is at increased risk of becoming an abuser toward the infant due to the following factors: young age, lack of a family support system, low education level, and being a new mother. There is not enough information to indicate that the child is at increased risk of cognitive delay or malnutrition. While the mother is staying with a male friend, the nurse cannot assume that the mother is at increased risk of becoming a victim of sexual violence. | M260: Health_Promotion | O260: Analysis
A261: 283 | B261: 3 | C261: 80 | D261: Practice | E261: The nurse is assessing a patient who presents with bright red, pruritic, crusty, and painful lesions. The parent notes that the child developed the rash after playing in the yard over the weekend. The nurse anticipates that the patient will MOST likely be referred to which of the following specialists? | F261: Allergist | G261: Hematologist | H261: Rheumatologist | I261: Dermatologist | J261: Allergist | K261: A | L261: The nurse suspects that the patient developed contact dermatitis after exposure to an allergen such as poison ivy. The patient will likely be referred to an allergist for patch testing. Because the diagnosis is contact dermatitis, a referral to a dermatologist is not necessary unless the rash does not resolve after treatment. A hematologist specializes in blood disorders, and a rheumatologist specializes in musculoskeletal conditions. | M261: Planning_and_Management | O261: Analysis
A262: 284 | B262: 2 | C262: 78 | D262: Practice | E262: While assessing a 3-year-old female patient during a wellness visit, the nurse notices blood in the child's underwear. Which of the following is the MOST accurate statement about this finding? | F262: It is a sign of neglect. | G262: It is a sign of physical abuse. | H262: It is a normal variant in girls due to hormone imbalances. | I262: It is a sign of sexual abuse. | J262: It is a sign of sexual abuse. | K262: D | L262: A 3-year-old girl should not have vaginal discharge or bleeding. Blood on undergarments, unusual odor in the genital area, and difficulty walking or sitting are all signs of sexual abuse in a patient of this age. Physical signs of abuse include bruises that resemble known objects, burn marks, and bruises and fractures in different stages of healing. Inadequate clothing and poor hygiene are two examples of possible signs of neglect. | M262: Assessment | O262: Application
A263: 285 | B263: 5 | C263: 76 | D263: Test | E263: A parent asks the nurse why their newborn son cannot breathe through the mouth when the nose is congested. The nurse's BEST response is: | F263: "You must open the infant's mouth to allow them to breathe." | G263: "Infants copy what they see, so you should breathe through your mouth to show the baby." | H263: "Infants breathe only through the nose until the age of 3 to 4 months." | I263: "Your child may have an oral defect that prevents breathing through the mouth." | J263: "Infants breathe only through the nose until the age of 3 to 4 months." | K263: C | L263: Infants breathe through their nose, even when congested, because they have not yet developed the ability to breathe through their mouths. That reflex typically develops at age 3 to 4 months. It is important to facilitate easier breathing by suctioning the infant’s nose if it is congested. The parent should not open the infant’s mouth to facilitate breathing. Infants do not have the ability to copy actions at this age, so there is no need for the parent to demonstrate the action. There are no indications that the newborn has an oral defect. | M263: Health_Promotion | O263: Application
A264: 286 | B264: 3 | C264: 81 | D264: Practice | E264: A child with a history of recurrent adenoiditis and sinusitis is a candidate for which surgery? | F264: Tonsillectomy | G264: Adenoidectomy | H264: Thyroidectomy | I264: Endoscopy | J264: Adenoidectomy | K264: B | L264: The patient is a candidate for an adenoidectomy, which is the removal of the adenoids. Palatine tonsils are removed during a tonsillectomy. Endoscopy is a diagnostic procedure that examines the esophagus and stomach. A thyroidectomy is the removal of all or part of the thyroid gland. | M264: Planning_and_Management | O264: Recall
A265: 287 | B265: 5 | C265: 77 | D265: Test | E265: When assessing the eyes of an infant with an ophthalmoscope, the nurse notes a white reflex, which indicates: | F265: Retinoblastoma | G265: A normal finding | H265: An eye infection | I265: Keratitis | J265: Retinoblastoma | K265: A | L265: Retinoblastoma, a malignant tumor of the retina, presents as a white reflex instead of the normal red reflex. It is an important finding that requires immediate referral to an ophthalmologist. It is not a normal finding or a sign of infection. Keratitis is an inflammation of the cornea. | M265: Assessment | O265: Recall
A266: 288 | B266: 5 | C266: 78 | D266: Test | E266: The nurse is caring for a 6-year-old patient with severe bacterial sinusitis and vomiting. The patient weighs 23 kg and has a nonsevere penicillin allergy. The nurse will prepare to administer which of the following? | F266: Ceftriaxone | G266: Cefdinir | H266: Amoxicillin | I266: Amoxicillin/clavulanate | J266: Cefdinir | K266: B | L266: Antibiotics should be prescribed for children with severe, worsening, or persistent acute bacterial sinusitis. Children with hypersensitivity to penicillin can be treated with cefdinir. Either amoxicillin or amoxicillin/clavulanate can be used as the first-line treatment in patients who do not have a penicillin allergy. Ceftriaxone IM can be given to children who are vomiting, who are unable take oral medications, or who do not have a penicillin allergy. | M266: Planning_and_Management | O266: Analysis
...

Sheet Batch planning - review
G1: Review of 4e Practice Test Items | M1: Review of 5e Knowledge Check Items
A2: Topic | C2: Recall Items (Planned) | D2: Application Items (Planned) | E2: Analysis Items (Planned) | F2: Total (Planned) | G2: Practice Test items from 4e (from Items tab) | H2: Teri Berry | I2: Amber Dortch | J2: Katherine Glass | K2: Tiffany Glass | L2: Uncommitted | M2: Knowledge Check items for 5e | N2: Teri Berry | O2: Amber Dortch | P2: Katherine Glass | Q2: Tiffany Glass | R2: Uncommitted | S2: Writer1 | T2: Writer2 | U2: Writer3 | V2: Writer4 | W2: Uncommitted | X2: Deviation from plan
C3: =SUM(C4:C18) -> 0 | D3: =SUM(D4:D18) -> 0 | E3: =SUM(E4:E18) -> 0 | F3: =SUM(C3:E3) -> 0 | G3: =SUM(G4:G18) -> #REF! | H3: =SUM(H4:H18) -> #REF! | I3: =SUM(I4:I18) -> #REF! | J3: =SUM(J4:J18) -> #REF! | K3: =SUM(K4:K18) -> #REF! | L3: =SUM(L4:L18) -> #REF! | M3: =SUM(M4:M18) -> #REF! | N3: =SUM(N4:N18) -> #REF! | ... W3: =SUM(W4:W18) -> #REF!
A4: Cardiovascular System | F4: =SUM(C4:E4) -> 0 | G4: =COUNTIFS(#REF!,$A4,#REF!,"N/A (4e)",#REF!,"Practice Test") -> #REF! | H4: =COUNTIFS(#REF!,$A4,#REF!,"N/A (4e)",#REF!,"Practice Test",#REF!,H$2) -> #REF! | I4: =COUNTIFS(#REF!,$A4,#REF!,"N/A (4e)",#REF!,"Practice Test",#REF!,I$2) -> #REF! | J4: =COUNTIFS(#REF!,$A4,#REF!,"N/A (4e)",#REF!,"Practice Test",#REF!,J$2) -> #REF! | K4: =COUNTIFS(#REF!,$A4,#REF!,"N/A (4e)",#REF!,"Practice Test",#REF!,K$2) -> #REF! | L4: =G4-SUM(H4:K4) -> #REF! | M4: =COUNTIFS(#REF!,$A4,#REF!,"<>N/A (4e)",#REF!,"Knowledge Check") -> #REF! | N4: =COUNTIFS(#REF!,$A4,#REF!,"Knowledge Check",#REF!,N$2) -> #REF! | O4: =COUNTIFS(#REF!,$A4,#REF!,"Knowledge Check",#REF!,O$2) -> #REF! | P4: =COUNTIFS(#REF!,$A4,#REF!,"Knowledge Check",#REF!,P$2) -> #REF! | Q4: =COUNTIFS(#REF!,$A4,#REF!,"Knowledge Check",#REF!,Q$2) -> #REF! | R4: =M4-SUM(N4:Q4) -> #REF! | W4: =F4-#REF! -> #REF! | X4: =G4-F4 -> #REF!
A5: Endocrine System | F5: =SUM(C5:E5) -> 0 | G5: =COUNTIFS(#REF!,$A5,#REF!,"N/A (4e)",#REF!,"Practice Test") -> #REF! | H5: =COUNTIFS(#REF!,$A5,#REF!,"N/A (4e)",#REF!,"Practice Test",#REF!,H$2) -> #REF! | I5: =COUNTIFS(#REF!,$A5,#REF!,"N/A (4e)",#REF!,"Practice Test",#REF!,I$2) -> #REF! | J5: =COUNTIFS(#REF!,$A5,#REF!,"N/A (4e)",#REF!,"Practice Test",#REF!,J$2) -> #REF! | K5: =COUNTIFS(#REF!,$A5,#REF!,"N/A (4e)",#REF!,"Practice Test",#REF!,K$2) -> #REF! | L5: =G5-SUM(H5:K5) -> #REF! | M5: =COUNTIFS(#REF!,$A5,#REF!,"<>N/A (4e)",#REF!,"Knowledge Check") -> #REF! | N5: =COUNTIFS(#REF!,$A5,#REF!,"Knowledge Check",#REF!,N$2) -> #REF! | O5: =COUNTIFS(#REF!,$A5,#REF!,"Knowledge Check",#REF!,O$2) -> #REF! | P5: =COUNTIFS(#REF!,$A5,#REF!,"Knowledge Check",#REF!,P$2) -> #REF! | Q5: =COUNTIFS(#REF!,$A5,#REF!,"Knowledge Check",#REF!,Q$2) -> #REF! | R5: =M5-SUM(N5:Q5) -> #REF! | X5: =G5-F5 -> #REF!
A6: Gastrointestinal System | F6: =SUM(C6:E6) -> 0 | G6: =COUNTIFS(#REF!,$A6,#REF!,"N/A (4e)",#REF!,"Practice Test") -> #REF! | H6: =COUNTIFS(#REF!,$A6,#REF!,"N/A (4e)",#REF!,"Practice Test",#REF!,H$2) -> #REF! | I6: =COUNTIFS(#REF!,$A6,#REF!,"N/A (4e)",#REF!,"Practice Test",#REF!,I$2) -> #REF! | J6: =COUNTIFS(#REF!,$A6,#REF!,"N/A (4e)",#REF!,"Practice Test",#REF!,J$2) -> #REF! | K6: =COUNTIFS(#REF!,$A6,#REF!,"N/A (4e)",#REF!,"Practice Test",#REF!,K$2) -> #REF! | L6: =G6-SUM(H6:K6) -> #REF! | M6: =COUNTIFS(#REF!,$A6,#REF!,"<>N/A (4e)",#REF!,"Knowledge Check") -> #REF! | N6: =COUNTIFS(#REF!,$A6,#REF!,"Knowledge Check",#REF!,N$2) -> #REF! | O6: =COUNTIFS(#REF!,$A6,#REF!,"Knowledge Check",#REF!,O$2) -> #REF! | P6: =COUNTIFS(#REF!,$A6,#REF!,"Knowledge Check",#REF!,P$2) -> #REF! | Q6: =COUNTIFS(#REF!,$A6,#REF!,"Knowledge Check",#REF!,Q$2) -> #REF! | R6: =M6-SUM(N6:Q6) -> #REF! | X6: =G6-F6 -> #REF!
A7: Genitourinary and Renal System | F7: =SUM(C7:E7) -> 0 | G7: =COUNTIFS(#REF!,$A7,#REF!,"N/A (4e)",#REF!,"Practice Test") -> #REF! | H7: =COUNTIFS(#REF!,$A7,#REF!,"N/A (4e)",#REF!,"Practice Test",#REF!,H$2) -> #REF! | I7: =COUNTIFS(#REF!,$A7,#REF!,"N/A (4e)",#REF!,"Practice Test",#REF!,I$2) -> #REF! | J7: =COUNTIFS(#REF!,$A7,#REF!,"N/A (4e)",#REF!,"Practice Test",#REF!,J$2) -> #REF! | K7: =COUNTIFS(#REF!,$A7,#REF!,"N/A (4e)",#REF!,"Practice Test",#REF!,K$2) -> #REF! | L7: =G7-SUM(H7:K7) -> #REF! | M7: =COUNTIFS(#REF!,$A7,#REF!,"<>N/A (4e)",#REF!,"Knowledge Check") -> #REF! | N7: =COUNTIFS(#REF!,$A7,#REF!,"Knowledge Check",#REF!,N$2) -> #REF! | O7: =COUNTIFS(#REF!,$A7,#REF!,"Knowledge Check",#REF!,O$2) -> #REF! | P7: =COUNTIFS(#REF!,$A7,#REF!,"Knowledge Check",#REF!,P$2) -> #REF! | Q7: =COUNTIFS(#REF!,$A7,#REF!,"Knowledge Check",#REF!,Q$2) -> #REF! | R7: =M7-SUM(N7:Q7) -> #REF! | X7: =G7-F7 -> #REF!
A8: Head, Eyes, Ears, Nose, and Throat | F8: =SUM(C8:E8) -> 0 | G8: =COUNTIFS(#REF!,$A8,#REF!,"N/A (4e)",#REF!,"Practice Test") -> #REF! | H8: =COUNTIFS(#REF!,$A8,#REF!,"N/A (4e)",#REF!,"Practice Test",#REF!,H$2) -> #REF! | I8: =COUNTIFS(#REF!,$A8,#REF!,"N/A (4e)",#REF!,"Practice Test",#REF!,I$2) -> #REF! | J8: =COUNTIFS(#REF!,$A8,#REF!,"N/A (4e)",#REF!,"Practice Test",#REF!,J$2) -> #REF! | K8: =COUNTIFS(#REF!,$A8,#REF!,"N/A (4e)",#REF!,"Practice Test",#REF!,K$2) -> #REF! | L8: =G8-SUM(H8:K8) -> #REF! | M8: =COUNTIFS(#REF!,$A8,#REF!,"<>N/A (4e)",#REF!,"Knowledge Check") -> #REF! | N8: =COUNTIFS(#REF!,$A8,#REF!,"Knowledge Check",#REF!,N$2) -> #REF! | O8: =COUNTIFS(#REF!,$A8,#REF!,"Knowledge Check",#REF!,O$2) -> #REF! | P8: =COUNTIFS(#REF!,$A8,#REF!,"Knowledge Check",#REF!,P$2) -> #REF! | Q8: =COUNTIFS(#REF!,$A8,#REF!,"Knowledge Check",#REF!,Q$2) -> #REF! | R8: =M8-SUM(N8:Q8) -> #REF! | X8: =G8-F8 -> #REF!
A9: Health Promotion, Screening, and Disease Prevention | F9: =SUM(C9:E9) -> 0 | G9: =COUNTIFS(#REF!,$A9,#REF!,"N/A (4e)",#REF!,"Practice Test") -> #REF! | H9: =COUNTIFS(#REF!,$A9,#REF!,"N/A (4e)",#REF!,"Practice Test",#REF!,H$2) -> #REF! | I9: =COUNTIFS(#REF!,$A9,#REF!,"N/A (4e)",#REF!,"Practice Test",#REF!,I$2) -> #REF! | J9: =COUNTIFS(#REF!,$A9,#REF!,"N/A (4e)",#REF!,"Practice Test",#REF!,J$2) -> #REF! | K9: =COUNTIFS(#REF!,$A9,#REF!,"N/A (4e)",#REF!,"Practice Test",#REF!,K$2) -> #REF! | L9: =G9-SUM(H9:K9) -> #REF! | M9: =COUNTIFS(#REF!,$A9,#REF!,"<>N/A (4e)",#REF!,"Knowledge Check") -> #REF! | N9: =COUNTIFS(#REF!,$A9,#REF!,"Knowledge Check",#REF!,N$2) -> #REF! | O9: =COUNTIFS(#REF!,$A9,#REF!,"Knowledge Check",#REF!,O$2) -> #REF! | P9: =COUNTIFS(#REF!,$A9,#REF!,"Knowledge Check",#REF!,P$2) -> #REF! | Q9: =COUNTIFS(#REF!,$A9,#REF!,"Knowledge Check",#REF!,Q$2) -> #REF! | R9: =M9-SUM(N9:Q9) -> #REF! | X9: =G9-F9 -> #REF!
A10: Hematopoietic System | F10: =SUM(C10:E10) -> 0 | G10: =COUNTIFS(#REF!,$A10,#REF!,"N/A (4e)",#REF!,"Practice Test") -> #REF! | H10: =COUNTIFS(#REF!,$A10,#REF!,"N/A (4e)",#REF!,"Practice Test",#REF!,H$2) -> #REF! | I10: =COUNTIFS(#REF!,$A10,#REF!,"N/A (4e)",#REF!,"Practice Test",#REF!,I$2) -> #REF! | J10: =COUNTIFS(#REF!,$A10,#REF!,"N/A (4e)",#REF!,"Practice Test",#REF!,J$2) -> #REF! | K10: =COUNTIFS(#REF!,$A10,#REF!,"N/A (4e)",#REF!,"Practice Test",#REF!,K$2) -> #REF! | L10: =G10-SUM(H10:K10) -> #REF! | M10: =COUNTIFS(#REF!,$A10,#REF!,"<>N/A (4e)",#REF!,"Knowledge Check") -> #REF! | N10: =COUNTIFS(#REF!,$A10,#REF!,"Knowledge Check",#REF!,N$2) -> #REF! | O10: =COUNTIFS(#REF!,$A10,#REF!,"Knowledge Check",#REF!,O$2) -> #REF! | P10: =COUNTIFS(#REF!,$A10,#REF!,"Knowledge Check",#REF!,P$2) -> #REF! | Q10: =COUNTIFS(#REF!,$A10,#REF!,"Knowledge Check",#REF!,Q$2) -> #REF! | R10: =M10-SUM(N10:Q10) -> #REF! | X10: =G10-F10 -> #REF!
A11: Integumentary System | F11: =SUM(C11:E11) -> 0 | G11: =COUNTIFS(#REF!,$A11,#REF!,"N/A (4e)",#REF!,"Practice Test") -> #REF! | H11: =COUNTIFS(#REF!,$A11,#REF!,"N/A (4e)",#REF!,"Practice Test",#REF!,H$2) -> #REF! | I11: =COUNTIFS(#REF!,$A11,#REF!,"N/A (4e)",#REF!,"Practice Test",#REF!,I$2) -> #REF! | J11: =COUNTIFS(#REF!,$A11,#REF!,"N/A (4e)",#REF!,"Practice Test",#REF!,J$2) -> #REF! | K11: =COUNTIFS(#REF!,$A11,#REF!,"N/A (4e)",#REF!,"Practice Test",#REF!,K$2) -> #REF! | L11: =G11-SUM(H11:K11) -> #REF! | M11: =COUNTIFS(#REF!,$A11,#REF!,"<>N/A (4e)",#REF!,"Knowledge Check") -> #REF! | N11: =COUNTIFS(#REF!,$A11,#REF!,"Knowledge Check",#REF!,N$2) -> #REF! | O11: =COUNTIFS(#REF!,$A11,#REF!,"Knowledge Check",#REF!,O$2) -> #REF! | P11: =COUNTIFS(#REF!,$A11,#REF!,"Knowledge Check",#REF!,P$2) -> #REF! | Q11: =COUNTIFS(#REF!,$A11,#REF!,"Knowledge Check",#REF!,Q$2) -> #REF! | R11: =M11-SUM(N11:Q11) -> #REF! | X11: =G11-F11 -> #REF!
A12: Musculoskeletal System | F12: =SUM(C12:E12) -> 0 | G12: =COUNTIFS(#REF!,$A12,#REF!,"N/A (4e)",#REF!,"Practice Test") -> #REF! | H12: =COUNTIFS(#REF!,$A12,#REF!,"N/A (4e)",#REF!,"Practice Test",#REF!,H$2) -> #REF! | I12: =COUNTIFS(#REF!,$A12,#REF!,"N/A (4e)",#REF!,"Practice Test",#REF!,I$2) -> #REF! | J12: =COUNTIFS(#REF!,$A12,#REF!,"N/A (4e)",#REF!,"Practice Test",#REF!,J$2) -> #REF! | K12: =COUNTIFS(#REF!,$A12,#REF!,"N/A (4e)",#REF!,"Practice Test",#REF!,K$2) -> #REF! | L12: =G12-SUM(H12:K12) -> #REF! | M12: =COUNTIFS(#REF!,$A12,#REF!,"<>N/A (4e)",#REF!,"Knowledge Check") -> #REF! | N12: =COUNTIFS(#REF!,$A12,#REF!,"Knowledge Check",#REF!,N$2) -> #REF! | O12: =COUNTIFS(#REF!,$A12,#REF!,"Knowledge Check",#REF!,O$2) -> #REF! | P12: =COUNTIFS(#REF!,$A12,#REF!,"Knowledge Check",#REF!,P$2) -> #REF! | Q12: =COUNTIFS(#REF!,$A12,#REF!,"Knowledge Check",#REF!,Q$2) -> #REF! | R12: =M12-SUM(N12:Q12) -> #REF! | X12: =G12-F12 -> #REF!
A13: Nervous System | F13: =SUM(C13:E13) -> 0 | G13: =COUNTIFS(#REF!,$A13,#REF!,"N/A (4e)",#REF!,"Practice Test") -> #REF! | H13: =COUNTIFS(#REF!,$A13,#REF!,"N/A (4e)",#REF!,"Practice Test",#REF!,H$2) -> #REF! | I13: =COUNTIFS(#REF!,$A13,#REF!,"N/A (4e)",#REF!,"Practice Test",#REF!,I$2) -> #REF! | J13: =COUNTIFS(#REF!,$A13,#REF!,"N/A (4e)",#REF!,"Practice Test",#REF!,J$2) -> #REF! | K13: =COUNTIFS(#REF!,$A13,#REF!,"N/A (4e)",#REF!,"Practice Test",#REF!,K$2) -> #REF! | L13: =G13-SUM(H13:K13) -> #REF! | M13: =COUNTIFS(#REF!,$A13,#REF!,"<>N/A (4e)",#REF!,"Knowledge Check") -> #REF! | N13: =COUNTIFS(#REF!,$A13,#REF!,"Knowledge Check",#REF!,N$2) -> #REF! | O13: =COUNTIFS(#REF!,$A13,#REF!,"Knowledge Check",#REF!,O$2) -> #REF! | P13: =COUNTIFS(#REF!,$A13,#REF!,"Knowledge Check",#REF!,P$2) -> #REF! | Q13: =COUNTIFS(#REF!,$A13,#REF!,"Knowledge Check",#REF!,Q$2) -> #REF! | R13: =M13-SUM(N13:Q13) -> #REF! | X13: =G13-F13 -> #REF!
A14: Pharmacology | F14: =SUM(C14:E14) -> 0 | G14: =COUNTIFS(#REF!,$A14,#REF!,"N/A (4e)",#REF!,"Practice Test") -> #REF! | H14: =COUNTIFS(#REF!,$A14,#REF!,"N/A (4e)",#REF!,"Practice Test",#REF!,H$2) -> #REF! | I14: =COUNTIFS(#REF!,$A14,#REF!,"N/A (4e)",#REF!,"Practice Test",#REF!,I$2) -> #REF! | J14: =COUNTIFS(#REF!,$A14,#REF!,"N/A (4e)",#REF!,"Practice Test",#REF!,J$2) -> #REF! | K14: =COUNTIFS(#REF!,$A14,#REF!,"N/A (4e)",#REF!,"Practice Test",#REF!,K$2) -> #REF! | L14: =G14-SUM(H14:K14) -> #REF! | M14: =COUNTIFS(#REF!,$A14,#REF!,"<>N/A (4e)",#REF!,"Knowledge Check") -> #REF! | N14: =COUNTIFS(#REF!,$A14,#REF!,"Knowledge Check",#REF!,N$2) -> #REF! | O14: =COUNTIFS(#REF!,$A14,#REF!,"Knowledge Check",#REF!,O$2) -> #REF! | P14: =COUNTIFS(#REF!,$A14,#REF!,"Knowledge Check",#REF!,P$2) -> #REF! | Q14: =COUNTIFS(#REF!,$A14,#REF!,"Knowledge Check",#REF!,Q$2) -> #REF! | R14: =M14-SUM(N14:Q14) -> #REF! | X14: =G14-F14 -> #REF!
A15: Professional Role | F15: =SUM(C15:E15) -> 0 | G15: =COUNTIFS(#REF!,$A15,#REF!,"N/A (4e)",#REF!,"Practice Test") -> #REF! | H15: =COUNTIFS(#REF!,$A15,#REF!,"N/A (4e)",#REF!,"Practice Test",#REF!,H$2) -> #REF! | I15: =COUNTIFS(#REF!,$A15,#REF!,"N/A (4e)",#REF!,"Practice Test",#REF!,I$2) -> #REF! | J15: =COUNTIFS(#REF!,$A15,#REF!,"N/A (4e)",#REF!,"Practice Test",#REF!,J$2) -> #REF! | K15: =COUNTIFS(#REF!,$A15,#REF!,"N/A (4e)",#REF!,"Practice Test",#REF!,K$2) -> #REF! | L15: =G15-SUM(H15:K15) -> #REF! | M15: =COUNTIFS(#REF!,$A15,#REF!,"<>N/A (4e)",#REF!,"Knowledge Check") -> #REF! | N15: =COUNTIFS(#REF!,$A15,#REF!,"Knowledge Check",#REF!,N$2) -> #REF! | O15: =COUNTIFS(#REF!,$A15,#REF!,"Knowledge Check",#REF!,O$2) -> #REF! | P15: =COUNTIFS(#REF!,$A15,#REF!,"Knowledge Check",#REF!,P$2) -> #REF! | Q15: =COUNTIFS(#REF!,$A15,#REF!,"Knowledge Check",#REF!,Q$2) -> #REF! | R15: =M15-SUM(N15:Q15) -> #REF! | X15: =G15-F15 -> #REF!
A16: Psychiatric-Mental Health | F16: =SUM(C16:E16) -> 0 | G16: =COUNTIFS(#REF!,$A16,#REF!,"N/A (4e)",#REF!,"Practice Test") -> #REF! | H16: =COUNTIFS(#REF!,$A16,#REF!,"N/A (4e)",#REF!,"Practice Test",#REF!,H$2) -> #REF! | I16: =COUNTIFS(#REF!,$A16,#REF!,"N/A (4e)",#REF!,"Practice Test",#REF!,I$2) -> #REF! | J16: =COUNTIFS(#REF!,$A16,#REF!,"N/A (4e)",#REF!,"Practice Test",#REF!,J$2) -> #REF! | K16: =COUNTIFS(#REF!,$A16,#REF!,"N/A (4e)",#REF!,"Practice Test",#REF!,K$2) -> #REF! | L16: =G16-SUM(H16:K16) -> #REF! | M16: =COUNTIFS(#REF!,$A16,#REF!,"<>N/A (4e)",#REF!,"Knowledge Check") -> #REF! | N16: =COUNTIFS(#REF!,$A16,#REF!,"Knowledge Check",#REF!,N$2) -> #REF! | O16: =COUNTIFS(#REF!,$A16,#REF!,"Knowledge Check",#REF!,O$2) -> #REF! | P16: =COUNTIFS(#REF!,$A16,#REF!,"Knowledge Check",#REF!,P$2) -> #REF! | Q16: =COUNTIFS(#REF!,$A16,#REF!,"Knowledge Check",#REF!,Q$2) -> #REF! | R16: =M16-SUM(N16:Q16) -> #REF! | X16: =G16-F16 -> #REF!
... A18: Respiratory System | F18: =SUM(C18:E18) -> 0 | G18: =COUNTIFS(#REF!,$A18,#REF!,"N/A (4e)",#REF!,"Practice Test") -> #REF! | H18: =COUNTIFS(#REF!,$A18,#REF!,"N/A (4e)",#REF!,"Practice Test",#REF!,H$2) -> #REF! | I18: =COUNTIFS(#REF!,$A18,#REF!,"N/A (4e)",#REF!,"Practice Test",#REF!,I$2) -> #REF! | J18: =COUNTIFS(#REF!,$A18,#REF!,"N/A (4e)",#REF!,"Practice Test",#REF!,J$2) -> #REF! | K18: =COUNTIFS(#REF!,$A18,#REF!,"N/A (4e)",#REF!,"Practice Test",#REF!,K$2) -> #REF! | L18: =G18-SUM(H18:K18) -> #REF! | M18: =COUNTIFS(#REF!,$A18,#REF!,"<>N/A (4e)",#REF!,"Knowledge Check") -> #REF! | N18: =COUNTIFS(#REF!,$A18,#REF!,"Knowledge Check",#REF!,N$2) -> #REF! | O18: =COUNTIFS(#REF!,$A18,#REF!,"Knowledge Check",#REF!,O$2) -> #REF! | P18: =COUNTIFS(#REF!,$A18,#REF!,"Knowledge Check",#REF!,P$2) -> #REF! | Q18: =COUNTIFS(#REF!,$A18,#REF!,"Knowledge Check",#REF!,Q$2) -> #REF! | R18: =M18-SUM(N18:Q18) -> #REF! | X18: =G18-F18 -> #REF!

Sheet Writing assignments
E1: All SMEs | J1: Remaining to assign | K1: GPT_DA | M1: Louise Comer | W1: Kathleen Andresen | AG1: Crystal Lane-Tillerson | AQ1: Kris Louque - REASSIGN | AV1: Christie Cavallo | BF1: Nan Pritchard | BP1: Portia Thomas | BZ1: SME 1
B2: Domain | C2: Subdomain | E2: Recall (Planned) | F2: Application (Planned) | G2: Reasoning (Planned) | H2: Total (Planned) | J2: =SUM(J5:J98) -> -1 | L2: Total | N2: Assigned total | O2: Assigned Recall | P2: Assigned App. | Q2: Assigned Analysis | S2: Actual total | T2: Actual Recall | U2: Actual App. | V2: Actual Analysis | X2: Assigned total | Y2: Assigned Recall | Z2: Assigned App. | AA2: Assigned Analysis | AC2: Actual total | AD2: Actual Recall | AE2: Actual App. | AF2: Actual Analysis | AH2: Assigned total | AI2: Assigned Recall | AJ2: Assigned App. | AK2: Assigned Analysis | AM2: Actual total | AN2: Actual Recall | AO2: Actual App. | AP2: Actual Analysis | AR2: Total | AS2: Recall | AT2: App. | AU2: Analysis | AW2: Assigned total | AX2: Assigned Recall | AY2: Assigned App. | AZ2: Assigned Analysis | BB2: Actual total | BC2: Actual Recall | BD2: Actual App. | BE2: Actual Analysis | BG2: Assigned total | BH2: Assigned Recall | BI2: Assigned App. | BJ2: Assigned Analysis | BL2: Actual total | BM2: Actual Recall | BN2: Actual App. | BO2: Actual Analysis | BQ2: Assigned total | BR2: Assigned Recall | BS2: Assigned App. | BT2: Assigned Analysis | BV2: Actual total | BW2: Actual Recall | BX2: Actual App. | BY2: Actual Analysis
E3: =SUM(E5:E98) -> 65 | F3: =SUM(F5:F98) -> 300 | G3: =SUM(G5:G98) -> 135 | H3: =SUM(E3:G3) -> 500 | L3: =SUM(L5:L98) -> 73 | N3: =SUM(N5:N98) -> 50 | O3: =SUM(O5:O98) -> 1 | P3: =SUM(P5:P98) -> 41 | Q3: =SUM(Q5:Q98) -> 8 | X3: =SUM(X5:X98) -> 82 | Y3: =SUM(Y5:Y98) -> 13 | Z3: =SUM(Z5:Z98) -> 45 | AA3: =SUM(AA5:AA98) -> 24 | AH3: =SUM(AH5:AH98) -> 82 | AI3: =SUM(AI5:AI98) -> 11 | AJ3: =SUM(AJ5:AJ98) -> 44 | AK3: =SUM(AK5:AK98) -> 27 | AR3: =SUM(AR5:AR98) -> 32 | AS3: =SUM(AS5:AS98) -> 5 | AT3: =SUM(AT5:AT98) -> 18 | AU3: =SUM(AU5:AU98) -> 9 | AW3: =SUM(AW5:AW98) -> 50 | AX3: =SUM(AX5:AX98) -> 7 | AY3: =SUM(AY5:AY98) -> 26 | AZ3: =SUM(AZ5:AZ98) -> 17 | BG3: =SUM(BG5:BG98) -> 82 | BH3: =SUM(BH5:BH98) -> 11 | BI3: =SUM(BI5:BI98) -> 47 | BJ3: =SUM(BJ5:BJ98) -> 24 | BQ3: =SUM(BQ5:BQ98) -> 82 | BR3: =SUM(BR5:BR98) -> 11 | BS3: =SUM(BS5:BS98) -> 45 | BT3: =SUM(BT5:BT98) -> 26
